Workbook
Name n_robot: Asumsi!$C$7
Name n_operasi: Asumsi!$C$8
Name jam_hari: Asumsi!$C$9
Name hari_tahun: Asumsi!$C$10
Name utilisasi: Asumsi!$C$11
Name jam_jalan: Asumsi!$C$12
Name jam_robot: Asumsi!$C$13
Name runtime: Asumsi!$C$15
Name n_cas: Asumsi!$C$16
Name umur_baterai: Asumsi!$C$17
Name umur_motor: Asumsi!$C$18
Name umur_ban: Asumsi!$C$19
Name umur_caster: Asumsi!$C$20
Name laju_modul: Asumsi!$C$21
Name laju_sensor: Asumsi!$C$22
Name mttr: Asumsi!$C$23
Name umk: Asumsi!$C$25
Name beban_upah: Asumsi!$C$26
Name jam_bulan: Asumsi!$C$27
Name tarif_teknisi: Asumsi!$C$28
Name eskalasi: Asumsi!$C$30
Name kontingensi: Asumsi!$C$31
Name tarif_listrik: Asumsi!$C$32
Name v_baterai: Asumsi!$C$33
Name kap_baterai: Asumsi!$C$34
Name efisiensi: Asumsi!$C$35
Name wh_cas: Asumsi!$C$36
Name panjang_lintasan: Asumsi!$C$37
Name ganti_lintasan: Asumsi!$C$38
Name pagu: Asumsi!$C$39
Name tahun_awal: Asumsi!$C$40
Name jam_pm: 'Jadwal PM'!$J$14
Name biaya_sc_tahun: 'Suku Cadang'!$M$25
Name biaya_stok_awal: 'Suku Cadang'!$N$25
Name jam_ganti: 'Suku Cadang'!$K$26
Name n_ganti: 'Suku Cadang'!$K$25

Sheet Ringkasan
A1: RENCANA ANGGARAN BIAYA (RAB) CAPEX & OPEX PEMELIHARAAN - 5 TAHUN
A2: Sistem: armada AGV mini line tracer, 5 unit (4 beroperasi + 1 cadangan), hasil PjBL P01 Kelompok 5
A3: Disusun oleh: Unit Maintenance | Diajukan kepada: Kepala Plant & Bagian Keuangan | Tugas Merancang RAB - Teknik Perawatan dan Perbaikan (B)
A4: Harga dalam Rupiah. Angka tahun 2-5 sudah termasuk eskalasi harga. Detail perhitungan di sheet Asumsi, Jadwal PM, Suku Cadang, CAPEX, dan OPEX.
A6: No | B6: Pos anggaran | C6: Tahun 1 | D6: Tahun 2 | E6: Tahun 3 | F6: Tahun 4 | G6: Tahun 5 | H6: Total 5 tahun | I6: % dari total
B7: Tahun anggaran | C7: =tahun_awal+0 | D7: =tahun_awal+1 | E7: =tahun_awal+2 | F7: =tahun_awal+3 | G7: =tahun_awal+4
A8: A | B8: CAPEX (pengadaan alat & stok awal)
A9: A.1 | B9: Peralatan kerja & alat ukur | C9: =SUMIFS(CAPEX!$I$6:$I$28,CAPEX!$B$6:$B$28,$B9,CAPEX!$J$6:$J$28,1) | D9: =SUMIFS(CAPEX!$I$6:$I$28,CAPEX!$B$6:$B$28,$B9,CAPEX!$J$6:$J$28,2) | E9: =SUMIFS(CAPEX!$I$6:$I$28,CAPEX!$B$6:$B$28,$B9,CAPEX!$J$6:$J$28,3) | F9: =SUMIFS(CAPEX!$I$6:$I$28,CAPEX!$B$6:$B$28,$B9,CAPEX!$J$6:$J$28,4) | G9: =SUMIFS(CAPEX!$I$6:$I$28,CAPEX!$B$6:$B$28,$B9,CAPEX!$J$6:$J$28,5) | H9: =SUM(C9:G9) | I9: =IF($H$23=0,0,H9/$H$23)
A10: A.2 | B10: Infrastruktur perawatan | C10: =SUMIFS(CAPEX!$I$6:$I$28,CAPEX!$B$6:$B$28,$B10,CAPEX!$J$6:$J$28,1) | D10: =SUMIFS(CAPEX!$I$6:$I$28,CAPEX!$B$6:$B$28,$B10,CAPEX!$J$6:$J$28,2) | E10: =SUMIFS(CAPEX!$I$6:$I$28,CAPEX!$B$6:$B$28,$B10,CAPEX!$J$6:$J$28,3) | F10: =SUMIFS(CAPEX!$I$6:$I$28,CAPEX!$B$6:$B$28,$B10,CAPEX!$J$6:$J$28,4) | G10: =SUMIFS(CAPEX!$I$6:$I$28,CAPEX!$B$6:$B$28,$B10,CAPEX!$J$6:$J$28,5) | H10: =SUM(C10:G10) | I10: =IF($H$23=0,0,H10/$H$23)
A11: A.3 | B11: Stok awal suku cadang kritis | C11: =SUMIFS(CAPEX!$I$6:$I$28,CAPEX!$B$6:$B$28,$B11,CAPEX!$J$6:$J$28,1) | D11: =SUMIFS(CAPEX!$I$6:$I$28,CAPEX!$B$6:$B$28,$B11,CAPEX!$J$6:$J$28,2) | E11: =SUMIFS(CAPEX!$I$6:$I$28,CAPEX!$B$6:$B$28,$B11,CAPEX!$J$6:$J$28,3) | F11: =SUMIFS(CAPEX!$I$6:$I$28,CAPEX!$B$6:$B$28,$B11,CAPEX!$J$6:$J$28,4) | G11: =SUMIFS(CAPEX!$I$6:$I$28,CAPEX!$B$6:$B$28,$B11,CAPEX!$J$6:$J$28,5) | H11: =SUM(C11:G11) | I11: =IF($H$23=0,0,H11/$H$23)
A12: A.4 | B12: Pelatihan & dokumentasi awal | C12: =SUMIFS(CAPEX!$I$6:$I$28,CAPEX!$B$6:$B$28,$B12,CAPEX!$J$6:$J$28,1) | D12: =SUMIFS(CAPEX!$I$6:$I$28,CAPEX!$B$6:$B$28,$B12,CAPEX!$J$6:$J$28,2) | E12: =SUMIFS(CAPEX!$I$6:$I$28,CAPEX!$B$6:$B$28,$B12,CAPEX!$J$6:$J$28,3) | F12: =SUMIFS(CAPEX!$I$6:$I$28,CAPEX!$B$6:$B$28,$B12,CAPEX!$J$6:$J$28,4) | G12: =SUMIFS(CAPEX!$I$6:$I$28,CAPEX!$B$6:$B$28,$B12,CAPEX!$J$6:$J$28,5) | H12: =SUM(C12:G12) | I12: =IF($H$23=0,0,H12/$H$23)
B13: Subtotal CAPEX | C13: =SUM(C9:C12) | D13: =SUM(D9:D12) | E13: =SUM(E9:E12) | F13: =SUM(F9:F12) | G13: =SUM(G9:G12) | H13: =SUM(H9:H12) | I13: =IF($H$23=0,0,H13/$H$23)
A14: B | B14: OPEX (biaya pemeliharaan rutin)
A15: B.1 | B15: Suku cadang penggantian | C15: =SUMIFS(OPEX!I$8:I$21,OPEX!$B$8:$B$21,$B15) | D15: =SUMIFS(OPEX!J$8:J$21,OPEX!$B$8:$B$21,$B15) | E15: =SUMIFS(OPEX!K$8:K$21,OPEX!$B$8:$B$21,$B15) | F15: =SUMIFS(OPEX!L$8:L$21,OPEX!$B$8:$B$21,$B15) | G15: =SUMIFS(OPEX!M$8:M$21,OPEX!$B$8:$B$21,$B15) | H15: =SUM(C15:G15) | I15: =IF($H$23=0,0,H15/$H$23)
A16: B.2 | B16: Bahan habis pakai | C16: =SUMIFS(OPEX!I$8:I$21,OPEX!$B$8:$B$21,$B16) | D16: =SUMIFS(OPEX!J$8:J$21,OPEX!$B$8:$B$21,$B16) | E16: =SUMIFS(OPEX!K$8:K$21,OPEX!$B$8:$B$21,$B16) | F16: =SUMIFS(OPEX!L$8:L$21,OPEX!$B$8:$B$21,$B16) | G16: =SUMIFS(OPEX!M$8:M$21,OPEX!$B$8:$B$21,$B16) | H16: =SUM(C16:G16) | I16: =IF($H$23=0,0,H16/$H$23)
A17: B.3 | B17: Tenaga kerja pemeliharaan | C17: =SUMIFS(OPEX!I$8:I$21,OPEX!$B$8:$B$21,$B17) | D17: =SUMIFS(OPEX!J$8:J$21,OPEX!$B$8:$B$21,$B17) | E17: =SUMIFS(OPEX!K$8:K$21,OPEX!$B$8:$B$21,$B17) | F17: =SUMIFS(OPEX!L$8:L$21,OPEX!$B$8:$B$21,$B17) | G17: =SUMIFS(OPEX!M$8:M$21,OPEX!$B$8:$B$21,$B17) | H17: =SUM(C17:G17) | I17: =IF($H$23=0,0,H17/$H$23)
A18: B.4 | B18: Kalibrasi alat ukur | C18: =SUMIFS(OPEX!I$8:I$21,OPEX!$B$8:$B$21,$B18) | D18: =SUMIFS(OPEX!J$8:J$21,OPEX!$B$8:$B$21,$B18) | E18: =SUMIFS(OPEX!K$8:K$21,OPEX!$B$8:$B$21,$B18) | F18: =SUMIFS(OPEX!L$8:L$21,OPEX!$B$8:$B$21,$B18) | G18: =SUMIFS(OPEX!M$8:M$21,OPEX!$B$8:$B$21,$B18) | H18: =SUM(C18:G18) | I18: =IF($H$23=0,0,H18/$H$23)
A19: B.5 | B19: Pelatihan penyegaran | C19: =SUMIFS(OPEX!I$8:I$21,OPEX!$B$8:$B$21,$B19) | D19: =SUMIFS(OPEX!J$8:J$21,OPEX!$B$8:$B$21,$B19) | E19: =SUMIFS(OPEX!K$8:K$21,OPEX!$B$8:$B$21,$B19) | F19: =SUMIFS(OPEX!L$8:L$21,OPEX!$B$8:$B$21,$B19) | G19: =SUMIFS(OPEX!M$8:M$21,OPEX!$B$8:$B$21,$B19) | H19: =SUM(C19:G19) | I19: =IF($H$23=0,0,H19/$H$23)
A20: B.6 | B20: Listrik pengisian baterai | C20: =SUMIFS(OPEX!I$8:I$21,OPEX!$B$8:$B$21,$B20) | D20: =SUMIFS(OPEX!J$8:J$21,OPEX!$B$8:$B$21,$B20) | E20: =SUMIFS(OPEX!K$8:K$21,OPEX!$B$8:$B$21,$B20) | F20: =SUMIFS(OPEX!L$8:L$21,OPEX!$B$8:$B$21,$B20) | G20: =SUMIFS(OPEX!M$8:M$21,OPEX!$B$8:$B$21,$B20) | H20: =SUM(C20:G20) | I20: =IF($H$23=0,0,H20/$H$23)
A21: B.7 | B21: Kontingensi (persentase di sheet Asumsi) | C21: =OPEX!I23 | D21: =OPEX!J23 | E21: =OPEX!K23 | F21: =OPEX!L23 | G21: =OPEX!M23 | H21: =SUM(C21:G21) | I21: =IF($H$23=0,0,H21/$H$23)
B22: Subtotal OPEX | C22: =SUM(C15:C21) | D22: =SUM(D15:D21) | E22: =SUM(E15:E21) | F22: =SUM(F15:F21) | G22: =SUM(G15:G21) | H22: =SUM(H15:H21) | I22: =IF($H$23=0,0,H22/$H$23)
B23: TOTAL RAB (CAPEX + OPEX) | C23: =C13+C22 | D23: =D13+D22 | E23: =E13+E22 | F23: =F13+F22 | G23: =G13+G22 | H23: =H13+H22 | I23: =IF($H$23=0,0,H23/$H$23)
B25: Kesesuaian dengan pagu
B26: Pagu anggaran 5 tahun | C26: =pagu
B27: Total RAB 5 tahun | C27: =H23
B28: Sisa pagu | C28: =pagu-H23
B29: Persentase pagu terpakai | C29: =IF(pagu=0,0,H23/pagu)
B30: Status | C30: =IF(H23<=pagu,"SESUAI - di bawah pagu","MELEBIHI PAGU - kurangi pos")
B32: Indikator pemeliharaan
B33: Rata-rata biaya pemeliharaan per robot per tahun (Rp) | C33: =H23/n_robot/5
B34: Rata-rata biaya pemeliharaan per jam jalan robot (Rp/jam) | C34: =H23/(jam_jalan*5)
B35: Jam teknisi preventif per tahun | C35: =jam_pm
B36: Jam teknisi penggantian komponen per tahun | C36: =jam_ganti
B37: Porsi jam preventif dari total jam teknisi | C37: =IF(jam_pm+jam_ganti=0,0,jam_pm/(jam_pm+jam_ganti))
B38: Jumlah penggantian komponen per tahun (kejadian) | C38: =n_ganti
B39: Biaya teknisi per jam (Rp) | C39: =tarif_teknisi
B41: Catatan
B42: 1. Harga robot tidak termasuk: robot sudah terpasang dan beroperasi; RAB ini hanya biaya pemeliharaannya.
B43: 2. CAPEX dibeli di tahun 1. Stok awal suku cadang kritis disimpan supaya robot rusak bisa langsung diperbaiki.
B44: 3. Kebutuhan suku cadang dihitung dari jam jalan (motor, ban, caster), siklus baterai, dan laju kerusakan modul.
...

Sheet Asumsi
A1: Asumsi & Parameter Perhitungan
A2: Sel biru berlatar kuning = asumsi yang boleh diubah. Semua angka di sheet lain dihitung ulang otomatis.
A3: Sel hitam = rumus. Sel hijau = mengambil angka dari sheet lain.
A5: No | B5: Parameter | C5: Nilai | D5: Satuan | E5: Sumber / dasar
A6: A | B6: Sistem & pola operasi
A7: 1 | B7: Jumlah robot terpasang | C7: 5 | D7: unit | E7: Skenario: armada AGV mini line tracer (hasil PjBL) pengantar part/kanban antar stasiun kerja; 4 unit jalan + 1 unit cadangan rotasi
A8: 2 | B8: Robot beroperasi bersamaan | C8: 4 | D8: unit | E8: Skenario: 1 unit selalu cadangan (dirotasi saat perawatan/pengisian)
A9: 3 | B9: Jam operasi per hari | C9: 8 | D9: jam | E9: Skenario: 1 shift
A10: 4 | B10: Hari operasi per tahun | C10: 300 | D10: hari | E10: Skenario: 6 hari kerja per minggu dikurangi libur nasional
A11: 5 | B11: Utilisasi robot selama shift | C11: 0.6 | D11: - | E11: Skenario: robot hanya berjalan saat ada misi antar (60% waktu shift)
A12: 6 | B12: Jam jalan armada per tahun | C12: =n_operasi*jam_hari*hari_tahun*utilisasi | D12: jam/tahun | E12: Dihitung: robot beroperasi x jam/hari x hari/tahun x utilisasi
A13: 7 | B13: Rata-rata jam jalan per robot per tahun | C13: =jam_jalan/n_robot | D13: jam/tahun | E13: Dihitung: beban dibagi rata ke semua robot karena rotasi
A14: B | B14: Umur & keandalan komponen
A15: 8 | B15: Waktu jalan per pengisian baterai | C15: 3 | D15: jam | E15: Charter proyek: baterai 2x18650, pemakaian +/-3 jam per pengisian
A16: 9 | B16: Jumlah pengisian baterai per tahun | C16: =jam_jalan/runtime | D16: kali/tahun | E16: Dihitung: jam jalan armada / waktu jalan per pengisian
A17: 10 | B17: Umur siklus sel 18650 | C17: 500 | D17: siklus | E17: Estimasi umum sel Li-ion konsumen (300-500 siklus sampai kapasitas 80%); dipakai nilai atas karena arus beban kecil
A18: 11 | B18: Umur motor N20 (motor DC sikat) | C18: 1000 | D18: jam | E18: Estimasi kelompok untuk motor DC sikat ukuran kecil; diverifikasi dari data riwayat tahun pertama
A19: 12 | B19: Umur ban roda silikon | C19: 1500 | D19: jam | E19: Estimasi kelompok (lantai pabrik halus); diverifikasi dari data riwayat
A20: 13 | B20: Umur ball caster | C20: 3000 | D20: jam | E20: Estimasi kelompok
A21: 14 | B21: Laju kerusakan modul elektronik | C21: 0.1 | D21: per unit per tahun | E21: Estimasi kelompok: 1 dari 10 modul rusak per tahun (salah colok, benturan, ESD)
A22: 15 | B22: Laju kerusakan sensor IR | C22: 0.05 | D22: per sensor per tahun | E22: Estimasi kelompok: sensor di bawah PCB jarang terbentur
A23: 16 | B23: Waktu rata-rata penggantian komponen (MTTR) | C23: 1 | D23: jam per kejadian | E23: Estimasi: modul dipasang lewat header/konektor; termasuk uji ulang di lintasan
A24: C | B24: Tenaga kerja
A25: 17 | B25: UMK Kota Surabaya 2026 | C25: 5288796 | D25: Rp/bulan | E25: Kepgub Jatim No. 100.3.3.1/937/013/2025 (berlaku 1 Jan 2026) - https://www.jawapos.com/surabaya-raya/2512250021/resmi-ini-daftar-umk-38-kabupatenkota-di-jawa-timur-2026-surabaya-nyaris-rp-53-juta
A26: 18 | B26: Beban BPJS + THR pemberi kerja | C26: 0.189 | D26: dari upah | E26: BPJS Kesehatan 4% + BPJS Ketenagakerjaan +/-6,5% (JHT 3,7%, JP 2%, JKK 0,54%, JKM 0,3%) + THR 1/12 (8,33%)
A27: 19 | B27: Pembagi upah per jam | C27: 173 | D27: jam/bulan | E27: PP 35/2021: upah sejam = 1/173 x upah sebulan
A28: 20 | B28: Biaya teknisi per jam | C28: =umk*(1+beban_upah)/jam_bulan | D28: Rp/jam | E28: Dihitung: UMK x (1 + beban) / 173. Teknisi pemeliharaan diasumsikan dibayar setara UMK Surabaya
A29: D | B29: Ekonomi, utilitas & lintasan
A30: 21 | B30: Eskalasi harga per tahun | C30: 0.035 | D30: per tahun | E30: Batas atas sasaran inflasi BI 2026-2027 (2,5% +/- 1%); inflasi Juni 2026 = 3,34% - https://ekonomi.republika.co.id/berita/t8fpk6423/bi-optimistis-inflasi-20262027-tetap-terkendali-dalam-target
A31: 22 | B31: Kontingensi OPEX | C31: 0.1 | D31: dari subtotal OPEX | E31: Cadangan untuk kerusakan di luar perkiraan dan kenaikan harga komponen impor
A32: 23 | B32: Tarif listrik industri I-3/TM | C32: 1114.74 | D32: Rp/kWh | E32: Tarif PLN nonsubsidi triwulan IV 2026 (tidak berubah dari triwulan III) - https://www.fortuneidn.com/news/tarif-listrik-per-1-oktober-2026-d7w02-00-lflgw-zwfyxs
A33: 24 | B33: Tegangan nominal baterai 2S | C33: 7.4 | D33: V | E33: Spesifikasi robot (2x18650 seri)
A34: 25 | B34: Kapasitas sel 18650 | C34: 2.6 | D34: Ah | E34: Sel 2.600 mAh
A35: 26 | B35: Efisiensi pengisian | C35: 0.85 | D35: - | E35: Estimasi charger boost 2S USB-C
A36: 27 | B36: Energi listrik per pengisian | C36: =v_baterai*kap_baterai/efisiensi | D36: Wh | E36: Dihitung: V x Ah / efisiensi
A37: 28 | B37: Panjang garis lintasan di lantai produksi | C37: 60 | D37: m | E37: Skenario tata letak: rute antar 4 stasiun dengan persimpangan 90 derajat
A38: 29 | B38: Bagian garis yang diganti per tahun | C38: 0.5 | D38: dari panjang | E38: Estimasi: pita aus karena lalu lintas troli dan pejalan kaki
A39: 30 | B39: Pagu anggaran 5 tahun | C39: 100000000 | D39: Rp | E39: Ketentuan tugas: dana maksimal Rp 100.000.000
A40: 31 | B40: Tahun anggaran pertama | C40: 2027 | D40: - | E40: Asumsi: sistem sudah beroperasi, anggaran pemeliharaan mulai tahun anggaran 2027

Sheet Jadwal PM
A1: Jadwal Pemeliharaan Preventif (per tahun)
A2: Jam kerja teknisi dari tabel ini menjadi biaya tenaga kerja preventif di sheet OPEX.
A3: Pemeriksaan awal shift dikerjakan operator (autonomous maintenance), jamnya dicatat tapi tidak dibiayakan di RAB ini.
A5: No | B5: Kegiatan | C5: Rincian pekerjaan | D5: Pelaksana | E5: Frekuensi | F5: Kali per tahun | G5: Durasi per objek (menit) | H5: Dasar | I5: Jumlah objek | J5: Jam per tahun | K5: Alat utama
A6: 1 | B6: Pemeriksaan awal shift | C6: Cek tegangan baterai di OLED, bersihkan sensor dengan kuas antistatis, cek roda & ball caster, uji jalan 1 putaran | D6: Operator | E6: Harian | F6: =hari_tahun | G6: 3 | H6: per robot | I6: =IF(H6="per robot",n_robot,1) | J6: =F6*G6/60*I6 | K6: Kuas antistatis
A7: 2 | B7: Pemeliharaan mingguan | C7: Bersihkan sensor IR dengan isopropyl alcohol, kencangkan baut & roda, cek kabel/konektor, cek tegangan sel & BMS, uji di lintasan kalibrasi | D7: Teknisi | E7: Mingguan | F7: 52 | G7: 10 | H7: per robot | I7: =IF(H7="per robot",n_robot,1) | J7: =F7*G7/60*I7 | K7: Multimeter, set perkakas, lintasan uji
A8: 3 | B8: Pemeliharaan bulanan | C8: Uji kapasitas & tahanan dalam baterai, ukur RPM & arus motor, cek sinyal encoder, unduh log kejadian & cek versi firmware | D8: Teknisi | E8: Bulanan | F8: 12 | G8: 30 | H8: per robot | I8: =IF(H8="per robot",n_robot,1) | J8: =F8*G8/60*I8 | K8: Battery analyzer, tachometer, osiloskop, laptop
A9: 4 | B9: Overhaul tahunan | C9: Bongkar total, bersihkan, ganti komponen sesuai kondisi, kalibrasi ulang sensor & PID, uji fungsi lengkap di lintasan 4x4 | D9: Teknisi | E9: Tahunan | F9: 1 | G9: 120 | H9: per robot | I9: =IF(H9="per robot",n_robot,1) | J9: =F9*G9/60*I9 | K9: Semua alat kerja
A10: 5 | B10: Inspeksi garis lintasan | C10: Cek pita garis terkelupas/kotor, tambal, bersihkan area persimpangan | D10: Teknisi | E10: Mingguan | F10: 52 | G10: 15 | H10: per sistem | I10: =IF(H10="per robot",n_robot,1) | J10: =F10*G10/60*I10 | K10: Pita garis, cutter
A11: 6 | B11: Perawatan perangkat lunak | C11: Backup firmware & parameter, pembaruan firmware, tinjau log kejadian & data downtime | D11: Teknisi | E11: Bulanan | F11: 12 | G11: 60 | H11: per sistem | I11: =IF(H11="per robot",n_robot,1) | J11: =F11*G11/60*I11 | K11: Laptop diagnostik
A12: 7 | B12: Stasiun pengisian & keselamatan | C12: Cek adaptor & kabel pengisian, kotak penyimpanan baterai, tekanan APAR | D12: Teknisi | E12: Bulanan | F12: 12 | G12: 30 | H12: per sistem | I12: =IF(H12="per robot",n_robot,1) | J12: =F12*G12/60*I12 | K12: Multimeter
B14: Jam teknisi per tahun (dibiayakan) | J14: =SUMIF(D6:D12,"Teknisi",J6:J12)
B15: Jam operator per tahun (tidak dibiayakan) | J15: =SUMIF(D6:D12,"Operator",J6:J12)

Sheet Suku Cadang
A1: Kebutuhan Suku Cadang per Tahun & Stok Awal Kritis
A2: Harga satuan = RAB PjBL revisi 3.4 (charter proyek). Kebutuhan dihitung dari jam jalan, siklus baterai, atau laju kerusakan di sheet Asumsi.
A3: Stok awal kritis dibeli sekali di tahun 1 (masuk CAPEX); kebutuhan per tahun masuk OPEX.
A5: No | B5: Komponen | C5: Satuan | D5: Harga satuan (Rp) | E5: Jumlah per robot | F5: Dasar penggantian | G5: Umur (jam / siklus) | H5: Laju kerusakan per tahun | I5: Kebutuhan per tahun | J5: Unit per penggantian | K5: Penggantian per tahun | L5: Stok awal kritis | M5: Biaya per tahun (Rp) | N5: Biaya stok awal (Rp) | O5: Sumber harga
A6: 1 | B6: Baterai Li-ion 18650 (2.600 mAh) | C6: pcs | D6: 40000 | E6: 2 | F6: Siklus baterai | G6: =umur_baterai | I6: =IF(F6="Siklus baterai",ROUNDUP(n_cas/G6*E6,0),IF(F6="Aus (jam)",ROUNDUP(jam_jalan*E6/G6,0),IF(F6="Kerusakan acak",ROUNDUP(n_robot*E6*H6,0),E6))) | J6: 2 | K6: =ROUNDUP(I6/J6,0) | L6: 4 | M6: =I6*D6 | N6: =L6*D6 | O6: RAB PjBL rev 3.4
A7: 2 | B7: Motor N20 6V 500 RPM + encoder | C7: pcs | D7: 55000 | E7: 2 | F7: Aus (jam) | G7: =umur_motor | I7: =IF(F7="Siklus baterai",ROUNDUP(n_cas/G7*E7,0),IF(F7="Aus (jam)",ROUNDUP(jam_jalan*E7/G7,0),IF(F7="Kerusakan acak",ROUNDUP(n_robot*E7*H7,0),E7))) | J7: 1 | K7: =ROUNDUP(I7/J7,0) | L7: 4 | M7: =I7*D7 | N7: =L7*D7 | O7: RAB PjBL rev 3.4
A8: 3 | B8: Roda + ban silikon N20 | C8: pasang | D8: 25000 | E8: 1 | F8: Aus (jam) | G8: =umur_ban | I8: =IF(F8="Siklus baterai",ROUNDUP(n_cas/G8*E8,0),IF(F8="Aus (jam)",ROUNDUP(jam_jalan*E8/G8,0),IF(F8="Kerusakan acak",ROUNDUP(n_robot*E8*H8,0),E8))) | J8: 1 | K8: =ROUNDUP(I8/J8,0) | L8: 2 | M8: =I8*D8 | N8: =L8*D8 | O8: RAB PjBL rev 3.4
A9: 4 | B9: Ball caster mini | C9: pcs | D9: 10000 | E9: 1 | F9: Aus (jam) | G9: =umur_caster | I9: =IF(F9="Siklus baterai",ROUNDUP(n_cas/G9*E9,0),IF(F9="Aus (jam)",ROUNDUP(jam_jalan*E9/G9,0),IF(F9="Kerusakan acak",ROUNDUP(n_robot*E9*H9,0),E9))) | J9: 1 | K9: =ROUNDUP(I9/J9,0) | L9: 1 | M9: =I9*D9 | N9: =L9*D9 | O9: RAB PjBL rev 3.4
A10: 5 | B10: Sensor IR ITR20001 | C10: pcs | D10: 3000 | E10: 5 | F10: Kerusakan acak | H10: =laju_sensor | I10: =IF(F10="Siklus baterai",ROUNDUP(n_cas/G10*E10,0),IF(F10="Aus (jam)",ROUNDUP(jam_jalan*E10/G10,0),IF(F10="Kerusakan acak",ROUNDUP(n_robot*E10*H10,0),E10))) | J10: 1 | K10: =ROUNDUP(I10/J10,0) | L10: 5 | M10: =I10*D10 | N10: =L10*D10 | O10: RAB PjBL rev 3.4
A11: 6 | B11: PCB sensor jangkar (fabrikasi) | C11: pcs | D11: 20000 | E11: 1 | F11: Kerusakan acak | H11: 0.1 | I11: =IF(F11="Siklus baterai",ROUNDUP(n_cas/G11*E11,0),IF(F11="Aus (jam)",ROUNDUP(jam_jalan*E11/G11,0),IF(F11="Kerusakan acak",ROUNDUP(n_robot*E11*H11,0),E11))) | J11: 1 | K11: =ROUNDUP(I11/J11,0) | L11: 1 | M11: =I11*D11 | N11: =L11*D11 | O11: RAB PjBL rev 3.4 (paket PCB / 5 lembar)
A12: 7 | B12: ESP32 DevKit 30 pin | C12: pcs | D12: 76000 | E12: 1 | F12: Kerusakan acak | H12: =laju_modul | I12: =IF(F12="Siklus baterai",ROUNDUP(n_cas/G12*E12,0),IF(F12="Aus (jam)",ROUNDUP(jam_jalan*E12/G12,0),IF(F12="Kerusakan acak",ROUNDUP(n_robot*E12*H12,0),E12))) | J12: 1 | K12: =ROUNDUP(I12/J12,0) | L12: 1 | M12: =I12*D12 | N12: =L12*D12 | O12: RAB PjBL rev 3.4
A13: 8 | B13: Modul driver motor TB6612FNG | C13: pcs | D13: 25000 | E13: 1 | F13: Kerusakan acak | H13: =laju_modul | I13: =IF(F13="Siklus baterai",ROUNDUP(n_cas/G13*E13,0),IF(F13="Aus (jam)",ROUNDUP(jam_jalan*E13/G13,0),IF(F13="Kerusakan acak",ROUNDUP(n_robot*E13*H13,0),E13))) | J13: 1 | K13: =ROUNDUP(I13/J13,0) | L13: 1 | M13: =I13*D13 | N13: =L13*D13 | O13: RAB PjBL rev 3.4
A14: 9 | B14: Modul buck MP1584 5 V | C14: pcs | D14: 10000 | E14: 1 | F14: Kerusakan acak | H14: =laju_modul | I14: =IF(F14="Siklus baterai",ROUNDUP(n_cas/G14*E14,0),IF(F14="Aus (jam)",ROUNDUP(jam_jalan*E14/G14,0),IF(F14="Kerusakan acak",ROUNDUP(n_robot*E14*H14,0),E14))) | J14: 1 | K14: =ROUNDUP(I14/J14,0) | L14: 1 | M14: =I14*D14 | N14: =L14*D14 | O14: RAB PjBL rev 3.4
A15: 10 | B15: Modul BMS 2S | C15: pcs | D15: 10000 | E15: 1 | F15: Kerusakan acak | H15: =laju_modul | I15: =IF(F15="Siklus baterai",ROUNDUP(n_cas/G15*E15,0),IF(F15="Aus (jam)",ROUNDUP(jam_jalan*E15/G15,0),IF(F15="Kerusakan acak",ROUNDUP(n_robot*E15*H15,0),E15))) | J15: 1 | K15: =ROUNDUP(I15/J15,0) | L15: 1 | M15: =I15*D15 | N15: =L15*D15 | O15: RAB PjBL rev 3.4
A16: 11 | B16: Modul charger 2S USB-C | C16: pcs | D16: 25000 | E16: 1 | F16: Kerusakan acak | H16: 0.2 | I16: =IF(F16="Siklus baterai",ROUNDUP(n_cas/G16*E16,0),IF(F16="Aus (jam)",ROUNDUP(jam_jalan*E16/G16,0),IF(F16="Kerusakan acak",ROUNDUP(n_robot*E16*H16,0),E16))) | J16: 1 | K16: =ROUNDUP(I16/J16,0) | L16: 1 | M16: =I16*D16 | N16: =L16*D16 | O16: RAB PjBL rev 3.4 (port dicolok tiap hari: laju 20%)
A17: 12 | B17: OLED 1,3 inci I2C | C17: pcs | D17: 52000 | E17: 1 | F17: Kerusakan acak | H17: 0.05 | I17: =IF(F17="Siklus baterai",ROUNDUP(n_cas/G17*E17,0),IF(F17="Aus (jam)",ROUNDUP(jam_jalan*E17/G17,0),IF(F17="Kerusakan acak",ROUNDUP(n_robot*E17*H17,0),E17))) | J17: 1 | K17: =ROUNDUP(I17/J17,0) | L17: 1 | M17: =I17*D17 | N17: =L17*D17 | O17: RAB PjBL rev 3.4
A18: 13 | B18: Holder baterai 2x18650 | C18: pcs | D18: 8000 | E18: 1 | F18: Kerusakan acak | H18: =laju_modul | I18: =IF(F18="Siklus baterai",ROUNDUP(n_cas/G18*E18,0),IF(F18="Aus (jam)",ROUNDUP(jam_jalan*E18/G18,0),IF(F18="Kerusakan acak",ROUNDUP(n_robot*E18*H18,0),E18))) | J18: 1 | K18: =ROUNDUP(I18/J18,0) | L18: 1 | M18: =I18*D18 | N18: =L18*D18 | O18: RAB PjBL rev 3.4
A19: 14 | B19: Saklar geser on/off | C19: pcs | D19: 3000 | E19: 1 | F19: Kerusakan acak | H19: =laju_modul | I19: =IF(F19="Siklus baterai",ROUNDUP(n_cas/G19*E19,0),IF(F19="Aus (jam)",ROUNDUP(jam_jalan*E19/G19,0),IF(F19="Kerusakan acak",ROUNDUP(n_robot*E19*H19,0),E19))) | J19: 1 | K19: =ROUNDUP(I19/J19,0) | L19: 2 | M19: =I19*D19 | N19: =L19*D19 | O19: RAB PjBL rev 3.4
A20: 15 | B20: Tombol tekan | C20: pcs | D20: 1000 | E20: 2 | F20: Kerusakan acak | H20: =laju_modul | I20: =IF(F20="Siklus baterai",ROUNDUP(n_cas/G20*E20,0),IF(F20="Aus (jam)",ROUNDUP(jam_jalan*E20/G20,0),IF(F20="Kerusakan acak",ROUNDUP(n_robot*E20*H20,0),E20))) | J20: 1 | K20: =ROUNDUP(I20/J20,0) | L20: 2 | M20: =I20*D20 | N20: =L20*D20 | O20: RAB PjBL rev 3.4
A21: 16 | B21: Buzzer | C21: pcs | D21: 3000 | E21: 1 | F21: Kerusakan acak | H21: 0.05 | I21: =IF(F21="Siklus baterai",ROUNDUP(n_cas/G21*E21,0),IF(F21="Aus (jam)",ROUNDUP(jam_jalan*E21/G21,0),IF(F21="Kerusakan acak",ROUNDUP(n_robot*E21*H21,0),E21))) | J21: 1 | K21: =ROUNDUP(I21/J21,0) | L21: 1 | M21: =I21*D21 | N21: =L21*D21 | O21: RAB PjBL rev 3.4
A22: 17 | B22: Konektor JST PH 6 pin + kabel motor | C22: set | D22: 5000 | E22: 2 | F22: Kerusakan acak | H22: 0.2 | I22: =IF(F22="Siklus baterai",ROUNDUP(n_cas/G22*E22,0),IF(F22="Aus (jam)",ROUNDUP(jam_jalan*E22/G22,0),IF(F22="Kerusakan acak",ROUNDUP(n_robot*E22*H22,0),E22))) | J22: 1 | K22: =ROUNDUP(I22/J22,0) | L22: 4 | M22: =I22*D22 | N22: =L22*D22 | O22: RAB PjBL rev 3.4
A23: 18 | B23: Paket komponen pasif (R, C, dioda SS14, header) | C23: paket | D23: 25000 | E23: 1 | F23: Tetap per tahun | I23: =IF(F23="Siklus baterai",ROUNDUP(n_cas/G23*E23,0),IF(F23="Aus (jam)",ROUNDUP(jam_jalan*E23/G23,0),IF(F23="Kerusakan acak",ROUNDUP(n_robot*E23*H23,0),E23))) | J23: 1 | K23: =ROUNDUP(I23/J23,0) | L23: 1 | M23: =I23*D23 | N23: =L23*D23 | O23: RAB PjBL rev 3.4
B25: Total | K25: =SUM(K6:K23) | M25: =SUM(M6:M23) | N25: =SUM(N6:N23)
B26: Jam teknisi untuk penggantian komponen per tahun | K26: =K25*mttr | L26: jam

Sheet CAPEX
A1: CAPEX Pemeliharaan (pengadaan sekali, tahun 1)
A2: Harga = estimasi harga pasar daring (marketplace) Oktober 2026 untuk barang setara; cek ulang saat pengadaan.
A3: Total = jumlah x harga x (1 + eskalasi)^(tahun ke - 1), supaya pengadaan yang digeser ke tahun lain ikut naik harga.
A5: No | B5: Kategori | C5: Uraian | D5: Spesifikasi (setara) | E5: Fungsi dalam pemeliharaan | F5: Satuan | G5: Jumlah | H5: Harga satuan (Rp) | I5: Total (Rp) | J5: Tahun ke- | K5: Sumber harga
A6: 1 | B6: Peralatan kerja & alat ukur | C6: Laptop diagnostik | D6: Core i3/Ryzen 3, RAM 8 GB, SSD 256 GB | E6: Unggah firmware ESP32, baca log serial, simpan data riwayat perawatan (CMMS sederhana) | F6: unit | G6: 1 | H6: 5500000 | I6: =G6*H6*(1+eskalasi)^(J6-1) | J6: 1 | K6: Estimasi marketplace Okt 2026
A7: 2 | B7: Peralatan kerja & alat ukur | C7: Osiloskop digital 2 kanal | D7: 100 MHz (setara Hantek DSO2C10) | E7: Cek sinyal PWM motor, pulsa encoder, dan keluaran sensor IR saat diagnosis | F7: unit | G7: 1 | H7: 2500000 | I7: =G7*H7*(1+eskalasi)^(J7-1) | J7: 1 | K7: Estimasi marketplace Okt 2026
A8: 3 | B8: Peralatan kerja & alat ukur | C8: Multimeter digital acuan | D8: True RMS (setara UNI-T UT61E+) | E8: Ukur tegangan sel & arus; jadi acuan verifikasi alat ukur lain (dikalibrasi tiap tahun) | F8: unit | G8: 1 | H8: 850000 | I8: =G8*H8*(1+eskalasi)^(J8-1) | J8: 1 | K8: Estimasi marketplace Okt 2026
A9: 4 | B9: Peralatan kerja & alat ukur | C9: Multimeter digital lapangan | D9: Setara UNI-T UT33D+ | E9: Pemeriksaan cepat saat PM mingguan | F9: unit | G9: 1 | H9: 250000 | I9: =G9*H9*(1+eskalasi)^(J9-1) | J9: 1 | K9: Estimasi marketplace Okt 2026
A10: 5 | B10: Peralatan kerja & alat ukur | C10: Solder station suhu terkendali | D10: Setara Quicko T12 | E10: Ganti konektor, header modul, kabel motor | F10: unit | G10: 1 | H10: 850000 | I10: =G10*H10*(1+eskalasi)^(J10-1) | J10: 1 | K10: Estimasi marketplace Okt 2026
A11: 6 | B11: Peralatan kerja & alat ukur | C11: Hot air rework station | D11: Setara 858D | E11: Ganti sensor ITR20001 & komponen SMD di PCB sensor | F11: unit | G11: 1 | H11: 750000 | I11: =G11*H11*(1+eskalasi)^(J11-1) | J11: 1 | K11: Estimasi marketplace Okt 2026
A12: 7 | B12: Peralatan kerja & alat ukur | C12: Catu daya DC laboratorium | D12: 30 V / 5 A | E12: Uji modul & motor di meja tanpa baterai | F12: unit | G12: 1 | H12: 900000 | I12: =G12*H12*(1+eskalasi)^(J12-1) | J12: 1 | K12: Estimasi marketplace Okt 2026
A13: 8 | B13: Peralatan kerja & alat ukur | C13: Penganalisis & pengisi baterai 18650 | D13: Setara LiitoKala Lii-500 (ukur kapasitas & IR) | E13: Uji kapasitas dan tahanan dalam sel saat PM bulanan, menentukan sel yang diganti | F13: unit | G13: 1 | H13: 450000 | I13: =G13*H13*(1+eskalasi)^(J13-1) | J13: 1 | K13: Estimasi marketplace Okt 2026
A14: 9 | B14: Peralatan kerja & alat ukur | C14: Tachometer optik digital | D14: Non-kontak | E14: Ukur RPM roda untuk mendeteksi motor yang mulai aus | F14: unit | G14: 1 | H14: 250000 | I14: =G14*H14*(1+eskalasi)^(J14-1) | J14: 1 | K14: Estimasi marketplace Okt 2026
A15: 10 | B15: Peralatan kerja & alat ukur | C15: Jangka sorong digital | D15: 150 mm | E15: Ukur keausan ban & dimensi suku cadang | F15: unit | G15: 1 | H15: 200000 | I15: =G15*H15*(1+eskalasi)^(J15-1) | J15: 1 | K15: Estimasi marketplace Okt 2026
A16: 11 | B16: Peralatan kerja & alat ukur | C16: Set perkakas elektronik | D16: Obeng presisi, tang, pinset, crimper JST, penyedot timah | E16: Bongkar pasang robot & pembuatan kabel | F16: set | G16: 1 | H16: 750000 | I16: =G16*H16*(1+eskalasi)^(J16-1) | J16: 1 | K16: Estimasi marketplace Okt 2026
A17: 12 | B17: Peralatan kerja & alat ukur | C17: Matras ESD + gelang antistatis + kaca pembesar berlampu | D17: - | E17: Mencegah kerusakan modul karena listrik statis saat perbaikan | F17: set | G17: 1 | H17: 600000 | I17: =G17*H17*(1+eskalasi)^(J17-1) | J17: 1 | K17: Estimasi marketplace Okt 2026
... A24: 19 | B24: Infrastruktur perawatan | C24: Jig uji sensor & encoder | D24: Rangka + PCB uji sederhana | E24: Uji PCB sensor & motor tanpa membongkar seluruh robot | F24: set | G24: 1 | H24: 400000 | I24: =G24*H24*(1+eskalasi)^(J24-1) | J24: 1 | K24: Estimasi marketplace Okt 2026
A25: 20 | B25: Stok awal suku cadang kritis | C25: Stok awal suku cadang kritis | D25: Rincian di sheet Suku Cadang | E25: Mengurangi downtime: robot langsung diperbaiki tanpa menunggu pengiriman | F25: paket | G25: 1 | H25: =biaya_stok_awal | I25: =G25*H25*(1+eskalasi)^(J25-1) | J25: 1 | K25: Sheet Suku Cadang
A26: 21 | B26: Pelatihan & dokumentasi awal | C26: Pelatihan awal teknisi & operator | D26: 2 hari, oleh tim perancang | E26: Teknisi paham perawatan, keselamatan baterai Li-ion, unggah firmware; operator paham pemeriksaan awal shift | F26: paket | G26: 1 | H26: 1500000 | I26: =G26*H26*(1+eskalasi)^(J26-1) | J26: 1 | K26: Estimasi kelompok
A27: 22 | B27: Pelatihan & dokumentasi awal | C27: Printer label aset / kode QR | D27: Setara Brother PT-E110 | E27: Label aset tiap robot & suku cadang, terhubung ke kartu riwayat perawatan | F27: unit | G27: 1 | H27: 500000 | I27: =G27*H27*(1+eskalasi)^(J27-1) | J27: 1 | K27: Estimasi marketplace Okt 2026
A28: 23 | B28: Pelatihan & dokumentasi awal | C28: Cetak SOP, checklist PM & kartu riwayat | D28: Laminasi | E28: Dokumen kerja di stasiun perawatan | F28: paket | G28: 1 | H28: 150000 | I28: =G28*H28*(1+eskalasi)^(J28-1) | J28: 1 | K28: Estimasi kelompok
C30: Total CAPEX | I30: =SUM(I6:I28)

Sheet OPEX
A1: OPEX Pemeliharaan per Tahun (harga naik sesuai eskalasi)
A2: Biaya tahun t = volume x harga tahun 1 x (1 + eskalasi)^(t - 1), hanya pada tahun kelipatan interval.
A3: Volume suku cadang, jam preventif, dan jam penggantian diambil dari sheet Suku Cadang dan Jadwal PM.
H5: indeks tahun | I5: 1 | J5: 2 | K5: 3 | L5: 4 | M5: 5
A6: No | B6: Kategori | C6: Uraian | D6: Dasar perhitungan | E6: Satuan | F6: Volume per tahun | G6: Harga satuan th-1 (Rp) | H6: Interval (tahun) | I6: Tahun 1 | J6: Tahun 2 | K6: Tahun 3 | L6: Tahun 4 | M6: Tahun 5 | N6: Total 5 tahun (Rp)
H7: tahun anggaran | I7: =tahun_awal+I5-1 | J7: =tahun_awal+J5-1 | K7: =tahun_awal+K5-1 | L7: =tahun_awal+L5-1 | M7: =tahun_awal+M5-1
A8: 1 | B8: Suku cadang penggantian | C8: Suku cadang penggantian | D8: Kebutuhan per tahun dari sheet Suku Cadang | E8: paket | F8: 1 | G8: =biaya_sc_tahun | H8: 1 | I8: =IF(MOD(I$5,$H8)=0,$F8*$G8*(1+eskalasi)^(I$5-1),0) | J8: =IF(MOD(J$5,$H8)=0,$F8*$G8*(1+eskalasi)^(J$5-1),0) | K8: =IF(MOD(K$5,$H8)=0,$F8*$G8*(1+eskalasi)^(K$5-1),0) | L8: =IF(MOD(L$5,$H8)=0,$F8*$G8*(1+eskalasi)^(L$5-1),0) | M8: =IF(MOD(M$5,$H8)=0,$F8*$G8*(1+eskalasi)^(M$5-1),0) | N8: =SUM(I8:M8)
A9: 2 | B9: Bahan habis pakai | C9: Timah solder + flux | D9: 1 paket per triwulan | E9: paket | F9: 4 | G9: 25000 | H9: 1 | I9: =IF(MOD(I$5,$H9)=0,$F9*$G9*(1+eskalasi)^(I$5-1),0) | J9: =IF(MOD(J$5,$H9)=0,$F9*$G9*(1+eskalasi)^(J$5-1),0) | K9: =IF(MOD(K$5,$H9)=0,$F9*$G9*(1+eskalasi)^(K$5-1),0) | L9: =IF(MOD(L$5,$H9)=0,$F9*$G9*(1+eskalasi)^(L$5-1),0) | M9: =IF(MOD(M$5,$H9)=0,$F9*$G9*(1+eskalasi)^(M$5-1),0) | N9: =SUM(I9:M9)
A10: 3 | B10: Bahan habis pakai | C10: Isopropyl alcohol 99% 1 L | D10: Pembersih sensor IR saat PM mingguan | E10: botol | F10: 2 | G10: 90000 | H10: 1 | I10: =IF(MOD(I$5,$H10)=0,$F10*$G10*(1+eskalasi)^(I$5-1),0) | J10: =IF(MOD(J$5,$H10)=0,$F10*$G10*(1+eskalasi)^(J$5-1),0) | K10: =IF(MOD(K$5,$H10)=0,$F10*$G10*(1+eskalasi)^(K$5-1),0) | L10: =IF(MOD(L$5,$H10)=0,$F10*$G10*(1+eskalasi)^(L$5-1),0) | M10: =IF(MOD(M$5,$H10)=0,$F10*$G10*(1+eskalasi)^(M$5-1),0) | N10: =SUM(I10:M10)
A11: 4 | B11: Bahan habis pakai | C11: Cotton bud + kain mikrofiber | D11: 1 paket per triwulan | E11: paket | F11: 4 | G11: 40000 | H11: 1 | I11: =IF(MOD(I$5,$H11)=0,$F11*$G11*(1+eskalasi)^(I$5-1),0) | J11: =IF(MOD(J$5,$H11)=0,$F11*$G11*(1+eskalasi)^(J$5-1),0) | K11: =IF(MOD(K$5,$H11)=0,$F11*$G11*(1+eskalasi)^(K$5-1),0) | L11: =IF(MOD(L$5,$H11)=0,$F11*$G11*(1+eskalasi)^(L$5-1),0) | M11: =IF(MOD(M$5,$H11)=0,$F11*$G11*(1+eskalasi)^(M$5-1),0) | N11: =SUM(I11:M11)
A12: 5 | B12: Bahan habis pakai | C12: Kabel AWG26, heat shrink, cable tie | D12: Perbaikan kabel motor & konektor | E12: paket | F12: 2 | G12: 75000 | H12: 1 | I12: =IF(MOD(I$5,$H12)=0,$F12*$G12*(1+eskalasi)^(I$5-1),0) | J12: =IF(MOD(J$5,$H12)=0,$F12*$G12*(1+eskalasi)^(J$5-1),0) | K12: =IF(MOD(K$5,$H12)=0,$F12*$G12*(1+eskalasi)^(K$5-1),0) | L12: =IF(MOD(L$5,$H12)=0,$F12*$G12*(1+eskalasi)^(L$5-1),0) | M12: =IF(MOD(M$5,$H12)=0,$F12*$G12*(1+eskalasi)^(M$5-1),0) | N12: =SUM(I12:M12)
A13: 6 | B13: Bahan habis pakai | C13: Baut, mur, spacer M3 | D13: Pengganti baut aus/hilang | E13: paket | F13: 4 | G13: 15000 | H13: 1 | I13: =IF(MOD(I$5,$H13)=0,$F13*$G13*(1+eskalasi)^(I$5-1),0) | J13: =IF(MOD(J$5,$H13)=0,$F13*$G13*(1+eskalasi)^(J$5-1),0) | K13: =IF(MOD(K$5,$H13)=0,$F13*$G13*(1+eskalasi)^(K$5-1),0) | L13: =IF(MOD(L$5,$H13)=0,$F13*$G13*(1+eskalasi)^(L$5-1),0) | M13: =IF(MOD(M$5,$H13)=0,$F13*$G13*(1+eskalasi)^(M$5-1),0) | N13: =SUM(I13:M13)
A14: 7 | B14: Bahan habis pakai | C14: Mata solder pengganti | D14: Aus pemakaian | E14: pcs | F14: 2 | G14: 60000 | H14: 1 | I14: =IF(MOD(I$5,$H14)=0,$F14*$G14*(1+eskalasi)^(I$5-1),0) | J14: =IF(MOD(J$5,$H14)=0,$F14*$G14*(1+eskalasi)^(J$5-1),0) | K14: =IF(MOD(K$5,$H14)=0,$F14*$G14*(1+eskalasi)^(K$5-1),0) | L14: =IF(MOD(L$5,$H14)=0,$F14*$G14*(1+eskalasi)^(L$5-1),0) | M14: =IF(MOD(M$5,$H14)=0,$F14*$G14*(1+eskalasi)^(M$5-1),0) | N14: =SUM(I14:M14)
A15: 8 | B15: Bahan habis pakai | C15: Contact cleaner spray | D15: Pembersih konektor & saklar | E15: kaleng | F15: 2 | G15: 65000 | H15: 1 | I15: =IF(MOD(I$5,$H15)=0,$F15*$G15*(1+eskalasi)^(I$5-1),0) | J15: =IF(MOD(J$5,$H15)=0,$F15*$G15*(1+eskalasi)^(J$5-1),0) | K15: =IF(MOD(K$5,$H15)=0,$F15*$G15*(1+eskalasi)^(K$5-1),0) | L15: =IF(MOD(L$5,$H15)=0,$F15*$G15*(1+eskalasi)^(L$5-1),0) | M15: =IF(MOD(M$5,$H15)=0,$F15*$G15*(1+eskalasi)^(M$5-1),0) | N15: =SUM(I15:M15)
A16: 9 | B16: Bahan habis pakai | C16: Pita garis lantai 19 mm (roll 33 m) | D16: Panjang lintasan x bagian yang diganti / 33 m per roll | E16: roll | F16: =ROUNDUP(panjang_lintasan*ganti_lintasan/33,0) | G16: 180000 | H16: 1 | I16: =IF(MOD(I$5,$H16)=0,$F16*$G16*(1+eskalasi)^(I$5-1),0) | J16: =IF(MOD(J$5,$H16)=0,$F16*$G16*(1+eskalasi)^(J$5-1),0) | K16: =IF(MOD(K$5,$H16)=0,$F16*$G16*(1+eskalasi)^(K$5-1),0) | L16: =IF(MOD(L$5,$H16)=0,$F16*$G16*(1+eskalasi)^(L$5-1),0) | M16: =IF(MOD(M$5,$H16)=0,$F16*$G16*(1+eskalasi)^(M$5-1),0) | N16: =SUM(I16:M16)
A17: 10 | B17: Tenaga kerja pemeliharaan | C17: Pemeliharaan preventif oleh teknisi | D17: Jam teknisi dari sheet Jadwal PM | E17: jam | F17: =jam_pm | G17: =tarif_teknisi | H17: 1 | I17: =IF(MOD(I$5,$H17)=0,$F17*$G17*(1+eskalasi)^(I$5-1),0) | J17: =IF(MOD(J$5,$H17)=0,$F17*$G17*(1+eskalasi)^(J$5-1),0) | K17: =IF(MOD(K$5,$H17)=0,$F17*$G17*(1+eskalasi)^(K$5-1),0) | L17: =IF(MOD(L$5,$H17)=0,$F17*$G17*(1+eskalasi)^(L$5-1),0) | M17: =IF(MOD(M$5,$H17)=0,$F17*$G17*(1+eskalasi)^(M$5-1),0) | N17: =SUM(I17:M17)
A18: 11 | B18: Tenaga kerja pemeliharaan | C18: Penggantian komponen (terencana + korektif) | D18: Jumlah penggantian x MTTR dari sheet Suku Cadang | E18: jam | F18: =jam_ganti | G18: =tarif_teknisi | H18: 1 | I18: =IF(MOD(I$5,$H18)=0,$F18*$G18*(1+eskalasi)^(I$5-1),0) | J18: =IF(MOD(J$5,$H18)=0,$F18*$G18*(1+eskalasi)^(J$5-1),0) | K18: =IF(MOD(K$5,$H18)=0,$F18*$G18*(1+eskalasi)^(K$5-1),0) | L18: =IF(MOD(L$5,$H18)=0,$F18*$G18*(1+eskalasi)^(L$5-1),0) | M18: =IF(MOD(M$5,$H18)=0,$F18*$G18*(1+eskalasi)^(M$5-1),0) | N18: =SUM(I18:M18)
A19: 12 | B19: Kalibrasi alat ukur | C19: Kalibrasi multimeter acuan (lab terakreditasi KAN) | D19: 1x per tahun; alat lain diverifikasi internal terhadap multimeter acuan | E19: kali | F19: 1 | G19: 400000 | H19: 1 | I19: =IF(MOD(I$5,$H19)=0,$F19*$G19*(1+eskalasi)^(I$5-1),0) | J19: =IF(MOD(J$5,$H19)=0,$F19*$G19*(1+eskalasi)^(J$5-1),0) | K19: =IF(MOD(K$5,$H19)=0,$F19*$G19*(1+eskalasi)^(K$5-1),0) | L19: =IF(MOD(L$5,$H19)=0,$F19*$G19*(1+eskalasi)^(L$5-1),0) | M19: =IF(MOD(M$5,$H19)=0,$F19*$G19*(1+eskalasi)^(M$5-1),0) | N19: =SUM(I19:M19)
A20: 13 | B20: Pelatihan penyegaran | C20: Pelatihan penyegaran teknisi & operator | D20: 1 hari per tahun, materi + konsumsi | E20: paket | F20: 1 | G20: 500000 | H20: 1 | I20: =IF(MOD(I$5,$H20)=0,$F20*$G20*(1+eskalasi)^(I$5-1),0) | J20: =IF(MOD(J$5,$H20)=0,$F20*$G20*(1+eskalasi)^(J$5-1),0) | K20: =IF(MOD(K$5,$H20)=0,$F20*$G20*(1+eskalasi)^(K$5-1),0) | L20: =IF(MOD(L$5,$H20)=0,$F20*$G20*(1+eskalasi)^(L$5-1),0) | M20: =IF(MOD(M$5,$H20)=0,$F20*$G20*(1+eskalasi)^(M$5-1),0) | N20: =SUM(I20:M20)
A21: 14 | B21: Listrik pengisian baterai | C21: Listrik pengisian baterai | D21: Jumlah pengisian x energi per pengisian / 1000 | E21: kWh | F21: =n_cas*wh_cas/1000 | G21: =tarif_listrik | H21: 1 | I21: =IF(MOD(I$5,$H21)=0,$F21*$G21*(1+eskalasi)^(I$5-1),0) | J21: =IF(MOD(J$5,$H21)=0,$F21*$G21*(1+eskalasi)^(J$5-1),0) | K21: =IF(MOD(K$5,$H21)=0,$F21*$G21*(1+eskalasi)^(K$5-1),0) | L21: =IF(MOD(L$5,$H21)=0,$F21*$G21*(1+eskalasi)^(L$5-1),0) | M21: =IF(MOD(M$5,$H21)=0,$F21*$G21*(1+eskalasi)^(M$5-1),0) | N21: =SUM(I21:M21)
C22: Subtotal sebelum kontingensi | I22: =SUM(I8:I21) | J22: =SUM(J8:J21) | K22: =SUM(K8:K21) | L22: =SUM(L8:L21) | M22: =SUM(M8:M21) | N22: =SUM(N8:N21)
B23: Kontingensi | C23: Kontingensi OPEX | D23: Persentase kontingensi x subtotal | I23: =kontingensi*I22 | J23: =kontingensi*J22 | K23: =kontingensi*K22 | L23: =kontingensi*L22 | M23: =kontingensi*M22 | N23: =SUM(I23:M23)
C24: Total OPEX | I24: =I22+I23 | J24: =J22+J23 | K24: =K22+K23 | L24: =L22+L23 | M24: =M22+M23 | N24: =N22+N23
